Workbook

Sheet HOW TO USE
A1: HOME SERVICES LEAD TRACKER — QUICK START GUIDE
A2: Follow these steps to get started with your tracker
A4: 1. OPENING IN GOOGLE SHEETS
A5: Upload this file to Google Drive (drive.google.com). Right-click the file > Open with > Google Sheets. All formulas, dropdowns, and conditional formatting will work automatically.
A7: 2. ENABLE FILTERS
A8: Go to Data > Create a filter. This adds filter arrows to every column header so you can sort and filter by status, service, area, date, etc.
A10: 3. COLOR CODES EXPLAINED
A11: GREEN = Confirmed / Payment Received | YELLOW = Pending / Advance NIL | RED = Cancelled / Payment Pending | BLUE = Scheduled | PURPLE tint = Completed | ORANGE = Refunded
A13: 4. USING THE LEAD TRACKER
A14: Start entering data from Row 4. The S.No, Order ID, Total Value, Discounted Total, Pending Balance, and Invoice Number columns auto-calculate via formulas. Use dropdowns for City, BHK, Services, Status, Payment, and Source fields.
A16: 5. CALENDAR / DATE PICKERS
A17: In Google Sheets, click any date cell (Preferred Date, Scheduled Date, Completed Date) and a calendar picker appears automatically. Dates are formatted DD-MMM-YYYY.
... A26: Keep the first 4 columns (A-D) visible — they are frozen. Use Order Source to track your best marketing channels. Regularly review the Dashboard for business insights. Back up your sheet weekly.

Sheet Lead Tracker
A1: HOME SERVICES — LEAD TRACKER & ORDER MANAGEMENT
A2: Comprehensive Lead Management for Home Services Business — Bangalore & Pan-India
A3: S.No | B3: Timestamp | C3: Order ID | D3: Customer Name | E3: Phone Number | F3: WhatsApp Number | G3: Alternate Phone | H3: Email | I3: City | J3: Area / Locality | K3: Full Address | L3: BHK | M3: SQFT | N3: Service 1 | O3: Price 1 | P3: Service 2 | Q3: Price 2 | R3: Service 3 | S3: Price 3 | T3: Service 4 | U3: Price 4 | V3: Total Value | W3: Discount Amount | X3: Discounted Total | Y3: Preferred Date | Z3: Slot Time | AA3: Order Source | AB3: Order Status | AC3: Reason / Notes | AD3: Vendor Name | AE3: Vendor Contact | AF3: Vendor Alternate No. | AG3: Order Scheduled Date | AH3: Scheduled Time | AI3: Order Completed Date | AJ3: Advance Amount | AK3: Advance Status | AL3: Pending Balance | AM3: Payment Value | AN3: Payment Status | AO3: Payment Mode | AP3: Refund Amount | AQ3: Invoice Number | AR3: Transaction Ref. No.
A4: =IF(B4<>"",ROW()-3,"") | B4: 46044.765 | C4: =IF(B4<>"","ST-"&TEXT(ROW()-3,"0000"),"") | D4: Rajesh Kumar | E4: 9876543210 | F4: 9876543210 | H4: rajesh.k@email.com | I4: Bangalore | J4: Indiranagar | K4: 123, 12th Main, Indiranagar, Bangalore - 560038 | L4: 2BHK | M4: 1200 | N4: Bathroom Cleaning | O4: 2000 | P4: Pest Control | Q4: 3500 | V4: =IF(COUNTA(N4)>0,SUM(O4,Q4,S4,U4),"") | W4: 500 | X4: =IF(V4<>"",V4-IF(W4<>"",W4,0),"") | Y4: 46051.765 | Z4: Morning 10-12 | AA4: Website | AB4: Confirmed | AD4: Suresh | AE4: 9988776655 | AG4: 46051.765 | AH4: Morning 10-12 | AJ4: 500 | AK4: Received | AL4: =IF(X4="","",IF(AN4="Received",0,X4-IF(AJ4<>"",AJ4,0))) | AQ4: =IF(B4<>"","INV-"&TEXT(ROW()-3,"0000"),"")
A5: =IF(B5<>"",ROW()-3,"") | B5: 46046.765 | C5: =IF(B5<>"","ST-"&TEXT(ROW()-3,"0000"),"") | D5: Priya Sharma | E5: 8765432109 | H5: priya.s@email.com | I5: Bangalore | J5: HSR Layout | K5: 45, Sector 2, HSR Layout, Bangalore - 560102 | L5: 3BHK | M5: 1800 | N5: Full Home Cleaning | O5: 4500 | V5: =IF(COUNTA(N5)>0,SUM(O5,Q5,S5,U5),"") | X5: =IF(V5<>"",V5-IF(W5<>"",W5,0),"") | Y5: 46054.765 | Z5: Afternoon 2-4 | AA5: Instagram | AB5: Pending | AL5: =IF(X5="","",IF(AN5="Received",0,X5-IF(AJ5<>"",AJ5,0))) | AQ5: =IF(B5<>"","INV-"&TEXT(ROW()-3,"0000"),"")
A6: =IF(B6<>"",ROW()-3,"") | B6: 46042.765 | C6: =IF(B6<>"","ST-"&TEXT(ROW()-3,"0000"),"") | D6: Amit Patel | E6: 7654321098 | H6: amit.p@email.com | I6: Bangalore | J6: Whitefield | K6: 78, ITPL Road, Whitefield, Bangalore - 560066 | L6: 2BHK | M6: 1100 | N6: Painting | O6: 15000 | P6: Plumbing | Q6: 2000 | V6: =IF(COUNTA(N6)>0,SUM(O6,Q6,S6,U6),"") | W6: 2000 | X6: =IF(V6<>"",V6-IF(W6<>"",W6,0),"") | AA6: Google | AB6: Cancelled | AC6: Price too high | AL6: =IF(X6="","",IF(AN6="Received",0,X6-IF(AJ6<>"",AJ6,0))) | AQ6: =IF(B6<>"","INV-"&TEXT(ROW()-3,"0000"),"")
A7: =IF(B7<>"",ROW()-3,"") | B7: 46047.765 | C7: =IF(B7<>"","ST-"&TEXT(ROW()-3,"0000"),"") | D7: Meera Reddy | E7: 6543210987 | F7: 6543210987 | H7: meera.r@email.com | I7: Bangalore | J7: Koramangala | K7: 22, 5th Block, Koramangala, Bangalore - 560095 | L7: 3BHK | M7: 1600 | N7: Full Home Cleaning | O7: 4500 | V7: =IF(COUNTA(N7)>0,SUM(O7,Q7,S7,U7),"") | X7: =IF(V7<>"",V7-IF(W7<>"",W7,0),"") | Y7: 46052.765 | Z7: Morning 8-10 | AA7: JustDial | AB7: Scheduled | AD7: Ramesh | AE7: 9876501234 | AG7: 46052.765 | AH7: Morning 8-10 | AJ7: 1000 | AK7: Received | AL7: =IF(X7="","",IF(AN7="Received",0,X7-IF(AJ7<>"",AJ7,0))) | AQ7: =IF(B7<>"","INV-"&TEXT(ROW()-3,"0000"),"")
A8: =IF(B8<>"",ROW()-3,"") | B8: 46039.765 | C8: =IF(B8<>"","ST-"&TEXT(ROW()-3,"0000"),"") | D8: Karthik Nair | E8: 5432109876 | H8: karthik.n@email.com | I8: Bangalore | J8: JP Nagar | K8: 56, 6th Phase, JP Nagar, Bangalore - 560078 | L8: 1BHK | M8: 650 | N8: Plumbing | O8: 1500 | V8: =IF(COUNTA(N8)>0,SUM(O8,Q8,S8,U8),"") | X8: =IF(V8<>"",V8-IF(W8<>"",W8,0),"") | Y8: 46041.765 | Z8: Evening 4-6 | AA8: Website | AB8: Completed | AD8: Vijay | AE8: 9123456780 | AG8: 46041.765 | AH8: Evening 4-6 | AI8: 46041.765 | AJ8: 0 | AK8: NIL | AL8: =IF(X8="","",IF(AN8="Received",0,X8-IF(AJ8<>"",AJ8,0))) | AM8: 1500 | AN8: Received | AO8: Cash | AP8: 0 | AQ8: =IF(B8<>"","INV-"&TEXT(ROW()-3,"0000"),"")
A9: =IF(B9<>"",ROW()-3,"") | C9: =IF(B9<>"","ST-"&TEXT(ROW()-3,"0000"),"") | V9: =IF(COUNTA(N9)>0,SUM(O9,Q9,S9,U9),"") | X9: =IF(V9<>"",V9-IF(W9<>"",W9,0),"") | AL9: =IF(X9="","",IF(AN9="Received",0,X9-IF(AJ9<>"",AJ9,0))) | AQ9: =IF(B9<>"","INV-"&TEXT(ROW()-3,"0000"),"")
A10: =IF(B10<>"",ROW()-3,"") | C10: =IF(B10<>"","ST-"&TEXT(ROW()-3,"0000"),"") | V10: =IF(COUNTA(N10)>0,SUM(O10,Q10,S10,U10),"") | X10: =IF(V10<>"",V10-IF(W10<>"",W10,0),"") | AL10: =IF(X10="","",IF(AN10="Received",0,X10-IF(AJ10<>"",AJ10,0))) | AQ10: =IF(B10<>"","INV-"&TEXT(ROW()-3,"0000"),"")
A11: =IF(B11<>"",ROW()-3,"") | C11: =IF(B11<>"","ST-"&TEXT(ROW()-3,"0000"),"") | V11: =IF(COUNTA(N11)>0,SUM(O11,Q11,S11,U11),"") | X11: =IF(V11<>"",V11-IF(W11<>"",W11,0),"") | AL11: =IF(X11="","",IF(AN11="Received",0,X11-IF(AJ11<>"",AJ11,0))) | AQ11: =IF(B11<>"","INV-"&TEXT(ROW()-3,"0000"),"")
A12: =IF(B12<>"",ROW()-3,"") | C12: =IF(B12<>"","ST-"&TEXT(ROW()-3,"0000"),"") | V12: =IF(COUNTA(N12)>0,SUM(O12,Q12,S12,U12),"") | X12: =IF(V12<>"",V12-IF(W12<>"",W12,0),"") | AL12: =IF(X12="","",IF(AN12="Received",0,X12-IF(AJ12<>"",AJ12,0))) | AQ12: =IF(B12<>"","INV-"&TEXT(ROW()-3,"0000"),"")
A13: =IF(B13<>"",ROW()-3,"") | C13: =IF(B13<>"","ST-"&TEXT(ROW()-3,"0000"),"") | V13: =IF(COUNTA(N13)>0,SUM(O13,Q13,S13,U13),"") | X13: =IF(V13<>"",V13-IF(W13<>"",W13,0),"") | AL13: =IF(X13="","",IF(AN13="Received",0,X13-IF(AJ13<>"",AJ13,0))) | AQ13: =IF(B13<>"","INV-"&TEXT(ROW()-3,"0000"),"")
A14: =IF(B14<>"",ROW()-3,"") | C14: =IF(B14<>"","ST-"&TEXT(ROW()-3,"0000"),"") | V14: =IF(COUNTA(N14)>0,SUM(O14,Q14,S14,U14),"") | X14: =IF(V14<>"",V14-IF(W14<>"",W14,0),"") | AL14: =IF(X14="","",IF(AN14="Received",0,X14-IF(AJ14<>"",AJ14,0))) | AQ14: =IF(B14<>"","INV-"&TEXT(ROW()-3,"0000"),"")
A15: =IF(B15<>"",ROW()-3,"") | C15: =IF(B15<>"","ST-"&TEXT(ROW()-3,"0000"),"") | V15: =IF(COUNTA(N15)>0,SUM(O15,Q15,S15,U15),"") | X15: =IF(V15<>"",V15-IF(W15<>"",W15,0),"") | AL15: =IF(X15="","",IF(AN15="Received",0,X15-IF(AJ15<>"",AJ15,0))) | AQ15: =IF(B15<>"","INV-"&TEXT(ROW()-3,"0000"),"")
A16: =IF(B16<>"",ROW()-3,"") | C16: =IF(B16<>"","ST-"&TEXT(ROW()-3,"0000"),"") | V16: =IF(COUNTA(N16)>0,SUM(O16,Q16,S16,U16),"") | X16: =IF(V16<>"",V16-IF(W16<>"",W16,0),"") | AL16: =IF(X16="","",IF(AN16="Received",0,X16-IF(AJ16<>"",AJ16,0))) | AQ16: =IF(B16<>"","INV-"&TEXT(ROW()-3,"0000"),"")
A17: =IF(B17<>"",ROW()-3,"") | C17: =IF(B17<>"","ST-"&TEXT(ROW()-3,"0000"),"") | V17: =IF(COUNTA(N17)>0,SUM(O17,Q17,S17,U17),"") | X17: =IF(V17<>"",V17-IF(W17<>"",W17,0),"") | AL17: =IF(X17="","",IF(AN17="Received",0,X17-IF(AJ17<>"",AJ17,0))) | AQ17: =IF(B17<>"","INV-"&TEXT(ROW()-3,"0000"),"")
A18: =IF(B18<>"",ROW()-3,"") | C18: =IF(B18<>"","ST-"&TEXT(ROW()-3,"0000"),"") | V18: =IF(COUNTA(N18)>0,SUM(O18,Q18,S18,U18),"") | X18: =IF(V18<>"",V18-IF(W18<>"",W18,0),"") | AL18: =IF(X18="","",IF(AN18="Received",0,X18-IF(AJ18<>"",AJ18,0))) | AQ18: =IF(B18<>"","INV-"&TEXT(ROW()-3,"0000"),"")
A19: =IF(B19<>"",ROW()-3,"") | C19: =IF(B19<>"","ST-"&TEXT(ROW()-3,"0000"),"") | V19: =IF(COUNTA(N19)>0,SUM(O19,Q19,S19,U19),"") | X19: =IF(V19<>"",V19-IF(W19<>"",W19,0),"") | AL19: =IF(X19="","",IF(AN19="Received",0,X19-IF(AJ19<>"",AJ19,0))) | AQ19: =IF(B19<>"","INV-"&TEXT(ROW()-3,"0000"),"")
A20: =IF(B20<>"",ROW()-3,"") | C20: =IF(B20<>"","ST-"&TEXT(ROW()-3,"0000"),"") | V20: =IF(COUNTA(N20)>0,SUM(O20,Q20,S20,U20),"") | X20: =IF(V20<>"",V20-IF(W20<>"",W20,0),"") | AL20: =IF(X20="","",IF(AN20="Received",0,X20-IF(AJ20<>"",AJ20,0))) | AQ20: =IF(B20<>"","INV-"&TEXT(ROW()-3,"0000"),"")
... A100: =IF(B100<>"",ROW()-3,"") | C100: =IF(B100<>"","ST-"&TEXT(ROW()-3,"0000"),"") | V100: =IF(COUNTA(N100)>0,SUM(O100,Q100,S100,U100),"") | X100: =IF(V100<>"",V100-IF(W100<>"",W100,0),"") | AL100: =IF(X100="","",IF(AN100="Received",0,X100-IF(AJ100<>"",AJ100,0))) | AQ100: =IF(B100<>"","INV-"&TEXT(ROW()-3,"0000"),"")

Sheet Dashboard
A1: DASHBOARD — BUSINESS ANALYTICS & STATS
A2: Auto-updated analytics from Lead Tracker data
A4: STATUS COLORS: | B4: Confirmed | C4: Pending | D4: Cancelled | E4: Scheduled | F4: Completed | G4: Refunded
A6: ORDER STATISTICS
A7: Total Orders | B7: Confirmed | C7: Pending | D7: Cancelled | E7: Scheduled | F7: Completed | G7: Refunded
A8: =COUNTIF('Lead Tracker'!C4:C1000,"ST-*") | B8: =COUNTIF('Lead Tracker'!AB4:AB1000,"Confirmed") | C8: =COUNTIF('Lead Tracker'!AB4:AB1000,"Pending") | D8: =COUNTIF('Lead Tracker'!AB4:AB1000,"Cancelled") | E8: =COUNTIF('Lead Tracker'!AB4:AB1000,"Scheduled") | F8: =COUNTIF('Lead Tracker'!AB4:AB1000,"Completed") | G8: =COUNTIF('Lead Tracker'!AB4:AB1000,"Refunded")
A10: PAYMENT SUMMARY
A11: Total Quoted | B11: Total Received | C11: Total Pending | D11: Cash Received | E11: UPI Received | F11: Card / Gateway | G11: Total Advance | H11: Total Refunds
A12: =SUMPRODUCT(('Lead Tracker'!X4:X1000<>"")*('Lead Tracker'!X4:X1000)) | B12: =SUMPRODUCT(('Lead Tracker'!AN4:AN1000="Received")*('Lead Tracker'!AM4:AM1000)) | C12: =SUMPRODUCT(('Lead Tracker'!AN4:AN1000="Pending")*('Lead Tracker'!AM4:AM1000)) | D12: =SUMPRODUCT(('Lead Tracker'!AO4:AO1000="Cash")*('Lead Tracker'!AN4:AN1000="Received")*('Lead Tracker'!AM4:AM1000)) | E12: =SUMPRODUCT(('Lead Tracker'!AO4:AO1000="UPI")*('Lead Tracker'!AN4:AN1000="Received")*('Lead Tracker'!AM4:AM1000)) | F12: =SUMPRODUCT((('Lead Tracker'!AO4:AO1000="Debit Card")+('Lead Tracker'!AO4:AO1000="Payment Gateway"))*('Lead Tracker'!AN4:AN1000="Received")*('Lead Tracker'!AM4:AM1000)) | G12: =SUMPRODUCT(('Lead Tracker'!AK4:AK1000="Received")*('Lead Tracker'!AJ4:AJ1000)) | H12: =SUM('Lead Tracker'!AP4:AP1000)
A14: DISCOUNT SUMMARY
A15: Orders with Discount | B15: Total Discount Given | C15: Avg Discount
A16: =COUNTIF('Lead Tracker'!W4:W1000,">"&0) | B16: =SUM('Lead Tracker'!W4:W1000) | C16: =IFERROR(AVERAGEIF('Lead Tracker'!W4:W1000,">"&0),0)
A18: ORDER SOURCE TRACKING
A19: Source | B19: Total Orders | C19: Confirmed | D19: Completed | E19: Revenue
A20: Website | B20: =COUNTIF('Lead Tracker'!AA4:AA1000,A20) | C20: =COUNTIFS('Lead Tracker'!AA4:AA1000,A20,'Lead Tracker'!AB4:AB1000,"Confirmed") | D20: =COUNTIFS('Lead Tracker'!AA4:AA1000,A20,'Lead Tracker'!AB4:AB1000,"Completed") | E20: =SUMPRODUCT(('Lead Tracker'!AA4:AA1000=A20)*('Lead Tracker'!AN4:AN1000="Received")*('Lead Tracker'!AM4:AM1000))
A21: Instagram | B21: =COUNTIF('Lead Tracker'!AA4:AA1000,A21) | C21: =COUNTIFS('Lead Tracker'!AA4:AA1000,A21,'Lead Tracker'!AB4:AB1000,"Confirmed") | D21: =COUNTIFS('Lead Tracker'!AA4:AA1000,A21,'Lead Tracker'!AB4:AB1000,"Completed") | E21: =SUMPRODUCT(('Lead Tracker'!AA4:AA1000=A21)*('Lead Tracker'!AN4:AN1000="Received")*('Lead Tracker'!AM4:AM1000))
A22: JustDial | B22: =COUNTIF('Lead Tracker'!AA4:AA1000,A22) | C22: =COUNTIFS('Lead Tracker'!AA4:AA1000,A22,'Lead Tracker'!AB4:AB1000,"Confirmed") | D22: =COUNTIFS('Lead Tracker'!AA4:AA1000,A22,'Lead Tracker'!AB4:AB1000,"Completed") | E22: =SUMPRODUCT(('Lead Tracker'!AA4:AA1000=A22)*('Lead Tracker'!AN4:AN1000="Received")*('Lead Tracker'!AM4:AM1000))
A23: Google | B23: =COUNTIF('Lead Tracker'!AA4:AA1000,A23) | C23: =COUNTIFS('Lead Tracker'!AA4:AA1000,A23,'Lead Tracker'!AB4:AB1000,"Confirmed") | D23: =COUNTIFS('Lead Tracker'!AA4:AA1000,A23,'Lead Tracker'!AB4:AB1000,"Completed") | E23: =SUMPRODUCT(('Lead Tracker'!AA4:AA1000=A23)*('Lead Tracker'!AN4:AN1000="Received")*('Lead Tracker'!AM4:AM1000))
A24: Referral | B24: =COUNTIF('Lead Tracker'!AA4:AA1000,A24) | C24: =COUNTIFS('Lead Tracker'!AA4:AA1000,A24,'Lead Tracker'!AB4:AB1000,"Confirmed") | D24: =COUNTIFS('Lead Tracker'!AA4:AA1000,A24,'Lead Tracker'!AB4:AB1000,"Completed") | E24: =SUMPRODUCT(('Lead Tracker'!AA4:AA1000=A24)*('Lead Tracker'!AN4:AN1000="Received")*('Lead Tracker'!AM4:AM1000))
A25: WhatsApp | B25: =COUNTIF('Lead Tracker'!AA4:AA1000,A25) | C25: =COUNTIFS('Lead Tracker'!AA4:AA1000,A25,'Lead Tracker'!AB4:AB1000,"Confirmed") | D25: =COUNTIFS('Lead Tracker'!AA4:AA1000,A25,'Lead Tracker'!AB4:AB1000,"Completed") | E25: =SUMPRODUCT(('Lead Tracker'!AA4:AA1000=A25)*('Lead Tracker'!AN4:AN1000="Received")*('Lead Tracker'!AM4:AM1000))
A26: Walk-in | B26: =COUNTIF('Lead Tracker'!AA4:AA1000,A26) | C26: =COUNTIFS('Lead Tracker'!AA4:AA1000,A26,'Lead Tracker'!AB4:AB1000,"Confirmed") | D26: =COUNTIFS('Lead Tracker'!AA4:AA1000,A26,'Lead Tracker'!AB4:AB1000,"Completed") | E26: =SUMPRODUCT(('Lead Tracker'!AA4:AA1000=A26)*('Lead Tracker'!AN4:AN1000="Received")*('Lead Tracker'!AM4:AM1000))
A27: Other | B27: =COUNTIF('Lead Tracker'!AA4:AA1000,A27) | C27: =COUNTIFS('Lead Tracker'!AA4:AA1000,A27,'Lead Tracker'!AB4:AB1000,"Confirmed") | D27: =COUNTIFS('Lead Tracker'!AA4:AA1000,A27,'Lead Tracker'!AB4:AB1000,"Completed") | E27: =SUMPRODUCT(('Lead Tracker'!AA4:AA1000=A27)*('Lead Tracker'!AN4:AN1000="Received")*('Lead Tracker'!AM4:AM1000))
A28: TOTAL | B28: =SUM(B20:B27) | C28: =SUM(C20:C27) | D28: =SUM(D20:D27) | E28: =SUM(E20:E27)
A30: SERVICE-WISE BREAKDOWN
A31: Service | B31: Total Orders | C31: Confirmed | D31: Scheduled | E31: Completed | F31: Pending | G31: Cancelled | H31: Revenue
A32: Bathroom Cleaning | B32: =COUNTIF('Lead Tracker'!N4:N1000,A32)+COUNTIF('Lead Tracker'!P4:P1000,A32)+COUNTIF('Lead Tracker'!R4:R1000,A32)+COUNTIF('Lead Tracker'!T4:T1000,A32) | C32: =COUNTIFS('Lead Tracker'!N4:N1000,A32,'Lead Tracker'!AB4:AB1000,"Confirmed")+COUNTIFS('Lead Tracker'!P4:P1000,A32,'Lead Tracker'!AB4:AB1000,"Confirmed")+COUNTIFS('Lead Tracker'!R4:R1000,A32,'Lead Tracker'!AB4:AB1000,"Confirmed")+COUNTIFS('Lead Tracker'!T4:T1000,A32,'Lead Tracker'!AB4:AB1000,"Confirmed") | D32: =COUNTIFS('Lead Tracker'!N4:N1000,A32,'Lead Tracker'!AB4:AB1000,"Scheduled")+COUNTIFS('Lead Tracker'!P4:P1000,A32,'Lead Tracker'!AB4:AB1000,"Scheduled")+COUNTIFS('Lead Tracker'!R4:R1000,A32,'Lead Tracker'!AB4:AB1000,"Scheduled")+COUNTIFS('Lead Tracker'!T4:T1000,A32,'Lead Tracker'!AB4:AB1000,"Scheduled") | E32: =COUNTIFS('Lead Tracker'!N4:N1000,A32,'Lead Tracker'!AB4:AB1000,"Completed")+COUNTIFS('Lead Tracker'!P4:P1000,A32,'Lead Tracker'!AB4:AB1000,"Completed")+COUNTIFS('Lead Tracker'!R4:R1000,A32,'Lead Tracker'!AB4:AB1000,"Completed")+COUNTIFS('Lead Tracker'!T4:T1000,A32,'Lead Tracker'!AB4:AB1000,"Completed") | F32: =COUNTIFS('Lead Tracker'!N4:N1000,A32,'Lead Tracker'!AB4:AB1000,"Pending")+COUNTIFS('Lead Tracker'!P4:P1000,A32,'Lead Tracker'!AB4:AB1000,"Pending")+COUNTIFS('Lead Tracker'!R4:R1000,A32,'Lead Tracker'!AB4:AB1000,"Pending")+COUNTIFS('Lead Tracker'!T4:T1000,A32,'Lead Tracker'!AB4:AB1000,"Pending") | G32: =COUNTIFS('Lead Tracker'!N4:N1000,A32,'Lead Tracker'!AB4:AB1000,"Cancelled")+COUNTIFS('Lead Tracker'!P4:P1000,A32,'Lead Tracker'!AB4:AB1000,"Cancelled")+COUNTIFS('Lead Tracker'!R4:R1000,A32,'Lead Tracker'!AB4:AB1000,"Cancelled")+COUNTIFS('Lead Tracker'!T4:T1000,A32,'Lead Tracker'!AB4:AB1000,"Cancelled") | H32: =SUMPRODUCT(('Lead Tracker'!N4:N1000=A32)*('Lead Tracker'!AN4:AN1000="Received")*('Lead Tracker'!O4:O1000))+SUMPRODUCT(('Lead Tracker'!P4:P1000=A32)*('Lead Tracker'!AN4:AN1000="Received")*('Lead Tracker'!Q4:Q1000))+SUMPRODUCT(('Lead Tracker'!R4:R1000=A32)*('Lead Tracker'!AN4:AN1000="Received")*('Lead Tracker'!S4:S1000))+SUMPRODUCT(('Lead Tracker'!T4:T1000=A32)*('Lead Tracker'!AN4:AN1000="Received")*('Lead Tracker'!U4:U1000))
A33: Kitchen Cleaning | B33: =COUNTIF('Lead Tracker'!N4:N1000,A33)+COUNTIF('Lead Tracker'!P4:P1000,A33)+COUNTIF('Lead Tracker'!R4:R1000,A33)+COUNTIF('Lead Tracker'!T4:T1000,A33) | C33: =COUNTIFS('Lead Tracker'!N4:N1000,A33,'Lead Tracker'!AB4:AB1000,"Confirmed")+COUNTIFS('Lead Tracker'!P4:P1000,A33,'Lead Tracker'!AB4:AB1000,"Confirmed")+COUNTIFS('Lead Tracker'!R4:R1000,A33,'Lead Tracker'!AB4:AB1000,"Confirmed")+COUNTIFS('Lead Tracker'!T4:T1000,A33,'Lead Tracker'!AB4:AB1000,"Confirmed") | D33: =COUNTIFS('Lead Tracker'!N4:N1000,A33,'Lead Tracker'!AB4:AB1000,"Scheduled")+COUNTIFS('Lead Tracker'!P4:P1000,A33,'Lead Tracker'!AB4:AB1000,"Scheduled")+COUNTIFS('Lead Tracker'!R4:R1000,A33,'Lead Tracker'!AB4:AB1000,"Scheduled")+COUNTIFS('Lead Tracker'!T4:T1000,A33,'Lead Tracker'!AB4:AB1000,"Scheduled") | E33: =COUNTIFS('Lead Tracker'!N4:N1000,A33,'Lead Tracker'!AB4:AB1000,"Completed")+COUNTIFS('Lead Tracker'!P4:P1000,A33,'Lead Tracker'!AB4:AB1000,"Completed")+COUNTIFS('Lead Tracker'!R4:R1000,A33,'Lead Tracker'!AB4:AB1000,"Completed")+COUNTIFS('Lead Tracker'!T4:T1000,A33,'Lead Tracker'!AB4:AB1000,"Completed") | F33: =COUNTIFS('Lead Tracker'!N4:N1000,A33,'Lead Tracker'!AB4:AB1000,"Pending")+COUNTIFS('Lead Tracker'!P4:P1000,A33,'Lead Tracker'!AB4:AB1000,"Pending")+COUNTIFS('Lead Tracker'!R4:R1000,A33,'Lead Tracker'!AB4:AB1000,"Pending")+COUNTIFS('Lead Tracker'!T4:T1000,A33,'Lead Tracker'!AB4:AB1000,"Pending") | G33: =COUNTIFS('Lead Tracker'!N4:N1000,A33,'Lead Tracker'!AB4:AB1000,"Cancelled")+COUNTIFS('Lead Tracker'!P4:P1000,A33,'Lead Tracker'!AB4:AB1000,"Cancelled")+COUNTIFS('Lead Tracker'!R4:R1000,A33,'Lead Tracker'!AB4:AB1000,"Cancelled")+COUNTIFS('Lead Tracker'!T4:T1000,A33,'Lead Tracker'!AB4:AB1000,"Cancelled") | H33: =SUMPRODUCT(('Lead Tracker'!N4:N1000=A33)*('Lead Tracker'!AN4:AN1000="Received")*('Lead Tracker'!O4:O1000))+SUMPRODUCT(('Lead Tracker'!P4:P1000=A33)*('Lead Tracker'!AN4:AN1000="Received")*('Lead Tracker'!Q4:Q1000))+SUMPRODUCT(('Lead Tracker'!R4:R1000=A33)*('Lead Tracker'!AN4:AN1000="Received")*('Lead Tracker'!S4:S1000))+SUMPRODUCT(('Lead Tracker'!T4:T1000=A33)*('Lead Tracker'!AN4:AN1000="Received")*('Lead Tracker'!U4:U1000))
A34: Full Home Cleaning | B34: =COUNTIF('Lead Tracker'!N4:N1000,A34)+COUNTIF('Lead Tracker'!P4:P1000,A34)+COUNTIF('Lead Tracker'!R4:R1000,A34)+COUNTIF('Lead Tracker'!T4:T1000,A34) | C34: =COUNTIFS('Lead Tracker'!N4:N1000,A34,'Lead Tracker'!AB4:AB1000,"Confirmed")+COUNTIFS('Lead Tracker'!P4:P1000,A34,'Lead Tracker'!AB4:AB1000,"Confirmed")+COUNTIFS('Lead Tracker'!R4:R1000,A34,'Lead Tracker'!AB4:AB1000,"Confirmed")+COUNTIFS('Lead Tracker'!T4:T1000,A34,'Lead Tracker'!AB4:AB1000,"Confirmed") | D34: =COUNTIFS('Lead Tracker'!N4:N1000,A34,'Lead Tracker'!AB4:AB1000,"Scheduled")+COUNTIFS('Lead Tracker'!P4:P1000,A34,'Lead Tracker'!AB4:AB1000,"Scheduled")+COUNTIFS('Lead Tracker'!R4:R1000,A34,'Lead Tracker'!AB4:AB1000,"Scheduled")+COUNTIFS('Lead Tracker'!T4:T1000,A34,'Lead Tracker'!AB4:AB1000,"Scheduled") | E34: =COUNTIFS('Lead Tracker'!N4:N1000,A34,'Lead Tracker'!AB4:AB1000,"Completed")+COUNTIFS('Lead Tracker'!P4:P1000,A34,'Lead Tracker'!AB4:AB1000,"Completed")+COUNTIFS('Lead Tracker'!R4:R1000,A34,'Lead Tracker'!AB4:AB1000,"Completed")+COUNTIFS('Lead Tracker'!T4:T1000,A34,'Lead Tracker'!AB4:AB1000,"Completed") | F34: =COUNTIFS('Lead Tracker'!N4:N1000,A34,'Lead Tracker'!AB4:AB1000,"Pending")+COUNTIFS('Lead Tracker'!P4:P1000,A34,'Lead Tracker'!AB4:AB1000,"Pending")+COUNTIFS('Lead Tracker'!R4:R1000,A34,'Lead Tracker'!AB4:AB1000,"Pending")+COUNTIFS('Lead Tracker'!T4:T1000,A34,'Lead Tracker'!AB4:AB1000,"Pending") | G34: =COUNTIFS('Lead Tracker'!N4:N1000,A34,'Lead Tracker'!AB4:AB1000,"Cancelled")+COUNTIFS('Lead Tracker'!P4:P1000,A34,'Lead Tracker'!AB4:AB1000,"Cancelled")+COUNTIFS('Lead Tracker'!R4:R1000,A34,'Lead Tracker'!AB4:AB1000,"Cancelled")+COUNTIFS('Lead Tracker'!T4:T1000,A34,'Lead Tracker'!AB4:AB1000,"Cancelled") | H34: =SUMPRODUCT(('Lead Tracker'!N4:N1000=A34)*('Lead Tracker'!AN4:AN1000="Received")*('Lead Tracker'!O4:O1000))+SUMPRODUCT(('Lead Tracker'!P4:P1000=A34)*('Lead Tracker'!AN4:AN1000="Received")*('Lead Tracker'!Q4:Q1000))+SUMPRODUCT(('Lead Tracker'!R4:R1000=A34)*('Lead Tracker'!AN4:AN1000="Received")*('Lead Tracker'!S4:S1000))+SUMPRODUCT(('Lead Tracker'!T4:T1000=A34)*('Lead Tracker'!AN4:AN1000="Received")*('Lead Tracker'!U4:U1000))
A35: Rental Property Cleaning | B35: =COUNTIF('Lead Tracker'!N4:N1000,A35)+COUNTIF('Lead Tracker'!P4:P1000,A35)+COUNTIF('Lead Tracker'!R4:R1000,A35)+COUNTIF('Lead Tracker'!T4:T1000,A35) | C35: =COUNTIFS('Lead Tracker'!N4:N1000,A35,'Lead Tracker'!AB4:AB1000,"Confirmed")+COUNTIFS('Lead Tracker'!P4:P1000,A35,'Lead Tracker'!AB4:AB1000,"Confirmed")+COUNTIFS('Lead Tracker'!R4:R1000,A35,'Lead Tracker'!AB4:AB1000,"Confirmed")+COUNTIFS('Lead Tracker'!T4:T1000,A35,'Lead Tracker'!AB4:AB1000,"Confirmed") | D35: =COUNTIFS('Lead Tracker'!N4:N1000,A35,'Lead Tracker'!AB4:AB1000,"Scheduled")+COUNTIFS('Lead Tracker'!P4:P1000,A35,'Lead Tracker'!AB4:AB1000,"Scheduled")+COUNTIFS('Lead Tracker'!R4:R1000,A35,'Lead Tracker'!AB4:AB1000,"Scheduled")+COUNTIFS('Lead Tracker'!T4:T1000,A35,'Lead Tracker'!AB4:AB1000,"Scheduled") | E35: =COUNTIFS('Lead Tracker'!N4:N1000,A35,'Lead Tracker'!AB4:AB1000,"Completed")+COUNTIFS('Lead Tracker'!P4:P1000,A35,'Lead Tracker'!AB4:AB1000,"Completed")+COUNTIFS('Lead Tracker'!R4:R1000,A35,'Lead Tracker'!AB4:AB1000,"Completed")+COUNTIFS('Lead Tracker'!T4:T1000,A35,'Lead Tracker'!AB4:AB1000,"Completed") | F35: =COUNTIFS('Lead Tracker'!N4:N1000,A35,'Lead Tracker'!AB4:AB1000,"Pending")+COUNTIFS('Lead Tracker'!P4:P1000,A35,'Lead Tracker'!AB4:AB1000,"Pending")+COUNTIFS('Lead Tracker'!R4:R1000,A35,'Lead Tracker'!AB4:AB1000,"Pending")+COUNTIFS('Lead Tracker'!T4:T1000,A35,'Lead Tracker'!AB4:AB1000,"Pending") | G35: =COUNTIFS('Lead Tracker'!N4:N1000,A35,'Lead Tracker'!AB4:AB1000,"Cancelled")+COUNTIFS('Lead Tracker'!P4:P1000,A35,'Lead Tracker'!AB4:AB1000,"Cancelled")+COUNTIFS('Lead Tracker'!R4:R1000,A35,'Lead Tracker'!AB4:AB1000,"Cancelled")+COUNTIFS('Lead Tracker'!T4:T1000,A35,'Lead Tracker'!AB4:AB1000,"Cancelled") | H35: =SUMPRODUCT(('Lead Tracker'!N4:N1000=A35)*('Lead Tracker'!AN4:AN1000="Received")*('Lead Tracker'!O4:O1000))+SUMPRODUCT(('Lead Tracker'!P4:P1000=A35)*('Lead Tracker'!AN4:AN1000="Received")*('Lead Tracker'!Q4:Q1000))+SUMPRODUCT(('Lead Tracker'!R4:R1000=A35)*('Lead Tracker'!AN4:AN1000="Received")*('Lead Tracker'!S4:S1000))+SUMPRODUCT(('Lead Tracker'!T4:T1000=A35)*('Lead Tracker'!AN4:AN1000="Received")*('Lead Tracker'!U4:U1000))
A36: Ready to Move In Cleaning | B36: =COUNTIF('Lead Tracker'!N4:N1000,A36)+COUNTIF('Lead Tracker'!P4:P1000,A36)+COUNTIF('Lead Tracker'!R4:R1000,A36)+COUNTIF('Lead Tracker'!T4:T1000,A36) | C36: =COUNTIFS('Lead Tracker'!N4:N1000,A36,'Lead Tracker'!AB4:AB1000,"Confirmed")+COUNTIFS('Lead Tracker'!P4:P1000,A36,'Lead Tracker'!AB4:AB1000,"Confirmed")+COUNTIFS('Lead Tracker'!R4:R1000,A36,'Lead Tracker'!AB4:AB1000,"Confirmed")+COUNTIFS('Lead Tracker'!T4:T1000,A36,'Lead Tracker'!AB4:AB1000,"Confirmed") | D36: =COUNTIFS('Lead Tracker'!N4:N1000,A36,'Lead Tracker'!AB4:AB1000,"Scheduled")+COUNTIFS('Lead Tracker'!P4:P1000,A36,'Lead Tracker'!AB4:AB1000,"Scheduled")+COUNTIFS('Lead Tracker'!R4:R1000,A36,'Lead Tracker'!AB4:AB1000,"Scheduled")+COUNTIFS('Lead Tracker'!T4:T1000,A36,'Lead Tracker'!AB4:AB1000,"Scheduled") | E36: =COUNTIFS('Lead Tracker'!N4:N1000,A36,'Lead Tracker'!AB4:AB1000,"Completed")+COUNTIFS('Lead Tracker'!P4:P1000,A36,'Lead Tracker'!AB4:AB1000,"Completed")+COUNTIFS('Lead Tracker'!R4:R1000,A36,'Lead Tracker'!AB4:AB1000,"Completed")+COUNTIFS('Lead Tracker'!T4:T1000,A36,'Lead Tracker'!AB4:AB1000,"Completed") | F36: =COUNTIFS('Lead Tracker'!N4:N1000,A36,'Lead Tracker'!AB4:AB1000,"Pending")+COUNTIFS('Lead Tracker'!P4:P1000,A36,'Lead Tracker'!AB4:AB1000,"Pending")+COUNTIFS('Lead Tracker'!R4:R1000,A36,'Lead Tracker'!AB4:AB1000,"Pending")+COUNTIFS('Lead Tracker'!T4:T1000,A36,'Lead Tracker'!AB4:AB1000,"Pending") | G36: =COUNTIFS('Lead Tracker'!N4:N1000,A36,'Lead Tracker'!AB4:AB1000,"Cancelled")+COUNTIFS('Lead Tracker'!P4:P1000,A36,'Lead Tracker'!AB4:AB1000,"Cancelled")+COUNTIFS('Lead Tracker'!R4:R1000,A36,'Lead Tracker'!AB4:AB1000,"Cancelled")+COUNTIFS('Lead Tracker'!T4:T1000,A36,'Lead Tracker'!AB4:AB1000,"Cancelled") | H36: =SUMPRODUCT(('Lead Tracker'!N4:N1000=A36)*('Lead Tracker'!AN4:AN1000="Received")*('Lead Tracker'!O4:O1000))+SUMPRODUCT(('Lead Tracker'!P4:P1000=A36)*('Lead Tracker'!AN4:AN1000="Received")*('Lead Tracker'!Q4:Q1000))+SUMPRODUCT(('Lead Tracker'!R4:R1000=A36)*('Lead Tracker'!AN4:AN1000="Received")*('Lead Tracker'!S4:S1000))+SUMPRODUCT(('Lead Tracker'!T4:T1000=A36)*('Lead Tracker'!AN4:AN1000="Received")*('Lead Tracker'!U4:U1000))
A37: Painting | B37: =COUNTIF('Lead Tracker'!N4:N1000,A37)+COUNTIF('Lead Tracker'!P4:P1000,A37)+COUNTIF('Lead Tracker'!R4:R1000,A37)+COUNTIF('Lead Tracker'!T4:T1000,A37) | C37: =COUNTIFS('Lead Tracker'!N4:N1000,A37,'Lead Tracker'!AB4:AB1000,"Confirmed")+COUNTIFS('Lead Tracker'!P4:P1000,A37,'Lead Tracker'!AB4:AB1000,"Confirmed")+COUNTIFS('Lead Tracker'!R4:R1000,A37,'Lead Tracker'!AB4:AB1000,"Confirmed")+COUNTIFS('Lead Tracker'!T4:T1000,A37,'Lead Tracker'!AB4:AB1000,"Confirmed") | D37: =COUNTIFS('Lead Tracker'!N4:N1000,A37,'Lead Tracker'!AB4:AB1000,"Scheduled")+COUNTIFS('Lead Tracker'!P4:P1000,A37,'Lead Tracker'!AB4:AB1000,"Scheduled")+COUNTIFS('Lead Tracker'!R4:R1000,A37,'Lead Tracker'!AB4:AB1000,"Scheduled")+COUNTIFS('Lead Tracker'!T4:T1000,A37,'Lead Tracker'!AB4:AB1000,"Scheduled") | E37: =COUNTIFS('Lead Tracker'!N4:N1000,A37,'Lead Tracker'!AB4:AB1000,"Completed")+COUNTIFS('Lead Tracker'!P4:P1000,A37,'Lead Tracker'!AB4:AB1000,"Completed")+COUNTIFS('Lead Tracker'!R4:R1000,A37,'Lead Tracker'!AB4:AB1000,"Completed")+COUNTIFS('Lead Tracker'!T4:T1000,A37,'Lead Tracker'!AB4:AB1000,"Completed") | F37: =COUNTIFS('Lead Tracker'!N4:N1000,A37,'Lead Tracker'!AB4:AB1000,"Pending")+COUNTIFS('Lead Tracker'!P4:P1000,A37,'Lead Tracker'!AB4:AB1000,"Pending")+COUNTIFS('Lead Tracker'!R4:R1000,A37,'Lead Tracker'!AB4:AB1000,"Pending")+COUNTIFS('Lead Tracker'!T4:T1000,A37,'Lead Tracker'!AB4:AB1000,"Pending") | G37: =COUNTIFS('Lead Tracker'!N4:N1000,A37,'Lead Tracker'!AB4:AB1000,"Cancelled")+COUNTIFS('Lead Tracker'!P4:P1000,A37,'Lead Tracker'!AB4:AB1000,"Cancelled")+COUNTIFS('Lead Tracker'!R4:R1000,A37,'Lead Tracker'!AB4:AB1000,"Cancelled")+COUNTIFS('Lead Tracker'!T4:T1000,A37,'Lead Tracker'!AB4:AB1000,"Cancelled") | H37: =SUMPRODUCT(('Lead Tracker'!N4:N1000=A37)*('Lead Tracker'!AN4:AN1000="Received")*('Lead Tracker'!O4:O1000))+SUMPRODUCT(('Lead Tracker'!P4:P1000=A37)*('Lead Tracker'!AN4:AN1000="Received")*('Lead Tracker'!Q4:Q1000))+SUMPRODUCT(('Lead Tracker'!R4:R1000=A37)*('Lead Tracker'!AN4:AN1000="Received")*('Lead Tracker'!S4:S1000))+SUMPRODUCT(('Lead Tracker'!T4:T1000=A37)*('Lead Tracker'!AN4:AN1000="Received")*('Lead Tracker'!U4:U1000))
A38: Pest Control | B38: =COUNTIF('Lead Tracker'!N4:N1000,A38)+COUNTIF('Lead Tracker'!P4:P1000,A38)+COUNTIF('Lead Tracker'!R4:R1000,A38)+COUNTIF('Lead Tracker'!T4:T1000,A38) | C38: =COUNTIFS('Lead Tracker'!N4:N1000,A38,'Lead Tracker'!AB4:AB1000,"Confirmed")+COUNTIFS('Lead Tracker'!P4:P1000,A38,'Lead Tracker'!AB4:AB1000,"Confirmed")+COUNTIFS('Lead Tracker'!R4:R1000,A38,'Lead Tracker'!AB4:AB1000,"Confirmed")+COUNTIFS('Lead Tracker'!T4:T1000,A38,'Lead Tracker'!AB4:AB1000,"Confirmed") | D38: =COUNTIFS('Lead Tracker'!N4:N1000,A38,'Lead Tracker'!AB4:AB1000,"Scheduled")+COUNTIFS('Lead Tracker'!P4:P1000,A38,'Lead Tracker'!AB4:AB1000,"Scheduled")+COUNTIFS('Lead Tracker'!R4:R1000,A38,'Lead Tracker'!AB4:AB1000,"Scheduled")+COUNTIFS('Lead Tracker'!T4:T1000,A38,'Lead Tracker'!AB4:AB1000,"Scheduled") | E38: =COUNTIFS('Lead Tracker'!N4:N1000,A38,'Lead Tracker'!AB4:AB1000,"Completed")+COUNTIFS('Lead Tracker'!P4:P1000,A38,'Lead Tracker'!AB4:AB1000,"Completed")+COUNTIFS('Lead Tracker'!R4:R1000,A38,'Lead Tracker'!AB4:AB1000,"Completed")+COUNTIFS('Lead Tracker'!T4:T1000,A38,'Lead Tracker'!AB4:AB1000,"Completed") | F38: =COUNTIFS('Lead Tracker'!N4:N1000,A38,'Lead Tracker'!AB4:AB1000,"Pending")+COUNTIFS('Lead Tracker'!P4:P1000,A38,'Lead Tracker'!AB4:AB1000,"Pending")+COUNTIFS('Lead Tracker'!R4:R1000,A38,'Lead Tracker'!AB4:AB1000,"Pending")+COUNTIFS('Lead Tracker'!T4:T1000,A38,'Lead Tracker'!AB4:AB1000,"Pending") | G38: =COUNTIFS('Lead Tracker'!N4:N1000,A38,'Lead Tracker'!AB4:AB1000,"Cancelled")+COUNTIFS('Lead Tracker'!P4:P1000,A38,'Lead Tracker'!AB4:AB1000,"Cancelled")+COUNTIFS('Lead Tracker'!R4:R1000,A38,'Lead Tracker'!AB4:AB1000,"Cancelled")+COUNTIFS('Lead Tracker'!T4:T1000,A38,'Lead Tracker'!AB4:AB1000,"Cancelled") | H38: =SUMPRODUCT(('Lead Tracker'!N4:N1000=A38)*('Lead Tracker'!AN4:AN1000="Received")*('Lead Tracker'!O4:O1000))+SUMPRODUCT(('Lead Tracker'!P4:P1000=A38)*('Lead Tracker'!AN4:AN1000="Received")*('Lead Tracker'!Q4:Q1000))+SUMPRODUCT(('Lead Tracker'!R4:R1000=A38)*('Lead Tracker'!AN4:AN1000="Received")*('Lead Tracker'!S4:S1000))+SUMPRODUCT(('Lead Tracker'!T4:T1000=A38)*('Lead Tracker'!AN4:AN1000="Received")*('Lead Tracker'!U4:U1000))
A39: Plumbing | B39: =COUNTIF('Lead Tracker'!N4:N1000,A39)+COUNTIF('Lead Tracker'!P4:P1000,A39)+COUNTIF('Lead Tracker'!R4:R1000,A39)+COUNTIF('Lead Tracker'!T4:T1000,A39) | C39: =COUNTIFS('Lead Tracker'!N4:N1000,A39,'Lead Tracker'!AB4:AB1000,"Confirmed")+COUNTIFS('Lead Tracker'!P4:P1000,A39,'Lead Tracker'!AB4:AB1000,"Confirmed")+COUNTIFS('Lead Tracker'!R4:R1000,A39,'Lead Tracker'!AB4:AB1000,"Confirmed")+COUNTIFS('Lead Tracker'!T4:T1000,A39,'Lead Tracker'!AB4:AB1000,"Confirmed") | D39: =COUNTIFS('Lead Tracker'!N4:N1000,A39,'Lead Tracker'!AB4:AB1000,"Scheduled")+COUNTIFS('Lead Tracker'!P4:P1000,A39,'Lead Tracker'!AB4:AB1000,"Scheduled")+COUNTIFS('Lead Tracker'!R4:R1000,A39,'Lead Tracker'!AB4:AB1000,"Scheduled")+COUNTIFS('Lead Tracker'!T4:T1000,A39,'Lead Tracker'!AB4:AB1000,"Scheduled") | E39: =COUNTIFS('Lead Tracker'!N4:N1000,A39,'Lead Tracker'!AB4:AB1000,"Completed")+COUNTIFS('Lead Tracker'!P4:P1000,A39,'Lead Tracker'!AB4:AB1000,"Completed")+COUNTIFS('Lead Tracker'!R4:R1000,A39,'Lead Tracker'!AB4:AB1000,"Completed")+COUNTIFS('Lead Tracker'!T4:T1000,A39,'Lead Tracker'!AB4:AB1000,"Completed") | F39: =COUNTIFS('Lead Tracker'!N4:N1000,A39,'Lead Tracker'!AB4:AB1000,"Pending")+COUNTIFS('Lead Tracker'!P4:P1000,A39,'Lead Tracker'!AB4:AB1000,"Pending")+COUNTIFS('Lead Tracker'!R4:R1000,A39,'Lead Tracker'!AB4:AB1000,"Pending")+COUNTIFS('Lead Tracker'!T4:T1000,A39,'Lead Tracker'!AB4:AB1000,"Pending") | G39: =COUNTIFS('Lead Tracker'!N4:N1000,A39,'Lead Tracker'!AB4:AB1000,"Cancelled")+COUNTIFS('Lead Tracker'!P4:P1000,A39,'Lead Tracker'!AB4:AB1000,"Cancelled")+COUNTIFS('Lead Tracker'!R4:R1000,A39,'Lead Tracker'!AB4:AB1000,"Cancelled")+COUNTIFS('Lead Tracker'!T4:T1000,A39,'Lead Tracker'!AB4:AB1000,"Cancelled") | H39: =SUMPRODUCT(('Lead Tracker'!N4:N1000=A39)*('Lead Tracker'!AN4:AN1000="Received")*('Lead Tracker'!O4:O1000))+SUMPRODUCT(('Lead Tracker'!P4:P1000=A39)*('Lead Tracker'!AN4:AN1000="Received")*('Lead Tracker'!Q4:Q1000))+SUMPRODUCT(('Lead Tracker'!R4:R1000=A39)*('Lead Tracker'!AN4:AN1000="Received")*('Lead Tracker'!S4:S1000))+SUMPRODUCT(('Lead Tracker'!T4:T1000=A39)*('Lead Tracker'!AN4:AN1000="Received")*('Lead Tracker'!U4:U1000))
A40: Electrician | B40: =COUNTIF('Lead Tracker'!N4:N1000,A40)+COUNTIF('Lead Tracker'!P4:P1000,A40)+COUNTIF('Lead Tracker'!R4:R1000,A40)+COUNTIF('Lead Tracker'!T4:T1000,A40) | C40: =COUNTIFS('Lead Tracker'!N4:N1000,A40,'Lead Tracker'!AB4:AB1000,"Confirmed")+COUNTIFS('Lead Tracker'!P4:P1000,A40,'Lead Tracker'!AB4:AB1000,"Confirmed")+COUNTIFS('Lead Tracker'!R4:R1000,A40,'Lead Tracker'!AB4:AB1000,"Confirmed")+COUNTIFS('Lead Tracker'!T4:T1000,A40,'Lead Tracker'!AB4:AB1000,"Confirmed") | D40: =COUNTIFS('Lead Tracker'!N4:N1000,A40,'Lead Tracker'!AB4:AB1000,"Scheduled")+COUNTIFS('Lead Tracker'!P4:P1000,A40,'Lead Tracker'!AB4:AB1000,"Scheduled")+COUNTIFS('Lead Tracker'!R4:R1000,A40,'Lead Tracker'!AB4:AB1000,"Scheduled")+COUNTIFS('Lead Tracker'!T4:T1000,A40,'Lead Tracker'!AB4:AB1000,"Scheduled") | E40: =COUNTIFS('Lead Tracker'!N4:N1000,A40,'Lead Tracker'!AB4:AB1000,"Completed")+COUNTIFS('Lead Tracker'!P4:P1000,A40,'Lead Tracker'!AB4:AB1000,"Completed")+COUNTIFS('Lead Tracker'!R4:R1000,A40,'Lead Tracker'!AB4:AB1000,"Completed")+COUNTIFS('Lead Tracker'!T4:T1000,A40,'Lead Tracker'!AB4:AB1000,"Completed") | F40: =COUNTIFS('Lead Tracker'!N4:N1000,A40,'Lead Tracker'!AB4:AB1000,"Pending")+COUNTIFS('Lead Tracker'!P4:P1000,A40,'Lead Tracker'!AB4:AB1000,"Pending")+COUNTIFS('Lead Tracker'!R4:R1000,A40,'Lead Tracker'!AB4:AB1000,"Pending")+COUNTIFS('Lead Tracker'!T4:T1000,A40,'Lead Tracker'!AB4:AB1000,"Pending") | G40: =COUNTIFS('Lead Tracker'!N4:N1000,A40,'Lead Tracker'!AB4:AB1000,"Cancelled")+COUNTIFS('Lead Tracker'!P4:P1000,A40,'Lead Tracker'!AB4:AB1000,"Cancelled")+COUNTIFS('Lead Tracker'!R4:R1000,A40,'Lead Tracker'!AB4:AB1000,"Cancelled")+COUNTIFS('Lead Tracker'!T4:T1000,A40,'Lead Tracker'!AB4:AB1000,"Cancelled") | H40: =SUMPRODUCT(('Lead Tracker'!N4:N1000=A40)*('Lead Tracker'!AN4:AN1000="Received")*('Lead Tracker'!O4:O1000))+SUMPRODUCT(('Lead Tracker'!P4:P1000=A40)*('Lead Tracker'!AN4:AN1000="Received")*('Lead Tracker'!Q4:Q1000))+SUMPRODUCT(('Lead Tracker'!R4:R1000=A40)*('Lead Tracker'!AN4:AN1000="Received")*('Lead Tracker'!S4:S1000))+SUMPRODUCT(('Lead Tracker'!T4:T1000=A40)*('Lead Tracker'!AN4:AN1000="Received")*('Lead Tracker'!U4:U1000))
A41: Other | B41: =COUNTIF('Lead Tracker'!N4:N1000,A41)+COUNTIF('Lead Tracker'!P4:P1000,A41)+COUNTIF('Lead Tracker'!R4:R1000,A41)+COUNTIF('Lead Tracker'!T4:T1000,A41) | C41: =COUNTIFS('Lead Tracker'!N4:N1000,A41,'Lead Tracker'!AB4:AB1000,"Confirmed")+COUNTIFS('Lead Tracker'!P4:P1000,A41,'Lead Tracker'!AB4:AB1000,"Confirmed")+COUNTIFS('Lead Tracker'!R4:R1000,A41,'Lead Tracker'!AB4:AB1000,"Confirmed")+COUNTIFS('Lead Tracker'!T4:T1000,A41,'Lead Tracker'!AB4:AB1000,"Confirmed") | D41: =COUNTIFS('Lead Tracker'!N4:N1000,A41,'Lead Tracker'!AB4:AB1000,"Scheduled")+COUNTIFS('Lead Tracker'!P4:P1000,A41,'Lead Tracker'!AB4:AB1000,"Scheduled")+COUNTIFS('Lead Tracker'!R4:R1000,A41,'Lead Tracker'!AB4:AB1000,"Scheduled")+COUNTIFS('Lead Tracker'!T4:T1000,A41,'Lead Tracker'!AB4:AB1000,"Scheduled") | E41: =COUNTIFS('Lead Tracker'!N4:N1000,A41,'Lead Tracker'!AB4:AB1000,"Completed")+COUNTIFS('Lead Tracker'!P4:P1000,A41,'Lead Tracker'!AB4:AB1000,"Completed")+COUNTIFS('Lead Tracker'!R4:R1000,A41,'Lead Tracker'!AB4:AB1000,"Completed")+COUNTIFS('Lead Tracker'!T4:T1000,A41,'Lead Tracker'!AB4:AB1000,"Completed") | F41: =COUNTIFS('Lead Tracker'!N4:N1000,A41,'Lead Tracker'!AB4:AB1000,"Pending")+COUNTIFS('Lead Tracker'!P4:P1000,A41,'Lead Tracker'!AB4:AB1000,"Pending")+COUNTIFS('Lead Tracker'!R4:R1000,A41,'Lead Tracker'!AB4:AB1000,"Pending")+COUNTIFS('Lead Tracker'!T4:T1000,A41,'Lead Tracker'!AB4:AB1000,"Pending") | G41: =COUNTIFS('Lead Tracker'!N4:N1000,A41,'Lead Tracker'!AB4:AB1000,"Cancelled")+COUNTIFS('Lead Tracker'!P4:P1000,A41,'Lead Tracker'!AB4:AB1000,"Cancelled")+COUNTIFS('Lead Tracker'!R4:R1000,A41,'Lead Tracker'!AB4:AB1000,"Cancelled")+COUNTIFS('Lead Tracker'!T4:T1000,A41,'Lead Tracker'!AB4:AB1000,"Cancelled") | H41: =SUMPRODUCT(('Lead Tracker'!N4:N1000=A41)*('Lead Tracker'!AN4:AN1000="Received")*('Lead Tracker'!O4:O1000))+SUMPRODUCT(('Lead Tracker'!P4:P1000=A41)*('Lead Tracker'!AN4:AN1000="Received")*('Lead Tracker'!Q4:Q1000))+SUMPRODUCT(('Lead Tracker'!R4:R1000=A41)*('Lead Tracker'!AN4:AN1000="Received")*('Lead Tracker'!S4:S1000))+SUMPRODUCT(('Lead Tracker'!T4:T1000=A41)*('Lead Tracker'!AN4:AN1000="Received")*('Lead Tracker'!U4:U1000))
A42: TOTAL | B42: =SUM(B32:B41) | C42: =SUM(C32:C41) | D42: =SUM(D32:D41) | E42: =SUM(E32:E41) | F42: =SUM(F32:F41) | G42: =SUM(G32:G41) | H42: =SUM(H32:H41)
A44: AREA-WISE ORDER DISTRIBUTION
A45: Area | B45: Total Orders | C45: Confirmed | D45: Completed | E45: Pending | F45: Revenue
A46: Indiranagar | B46: =COUNTIF('Lead Tracker'!J4:J1000,A46) | C46: =COUNTIFS('Lead Tracker'!J4:J1000,A46,'Lead Tracker'!AB4:AB1000,"Confirmed") | D46: =COUNTIFS('Lead Tracker'!J4:J1000,A46,'Lead Tracker'!AB4:AB1000,"Completed") | E46: =COUNTIFS('Lead Tracker'!J4:J1000,A46,'Lead Tracker'!AB4:AB1000,"Pending") | F46: =SUMPRODUCT(('Lead Tracker'!J4:J1000=A46)*('Lead Tracker'!AN4:AN1000="Received")*('Lead Tracker'!AM4:AM1000))
A47: Koramangala | B47: =COUNTIF('Lead Tracker'!J4:J1000,A47) | C47: =COUNTIFS('Lead Tracker'!J4:J1000,A47,'Lead Tracker'!AB4:AB1000,"Confirmed") | D47: =COUNTIFS('Lead Tracker'!J4:J1000,A47,'Lead Tracker'!AB4:AB1000,"Completed") | E47: =COUNTIFS('Lead Tracker'!J4:J1000,A47,'Lead Tracker'!AB4:AB1000,"Pending") | F47: =SUMPRODUCT(('Lead Tracker'!J4:J1000=A47)*('Lead Tracker'!AN4:AN1000="Received")*('Lead Tracker'!AM4:AM1000))
...

Sheet Form Fields Reference
A1: GOOGLE FORM — FIELD REFERENCE
A2: Use this as a reference when creating your Google Form for lead capture
A3: Field Name | B3: Field Type | C3: Options / Notes
A4: Customer Name | B4: Short Answer | C4: Required. Full name of the customer.
A5: Phone Number | B5: Short Answer | C5: Required. Primary contact number (10 digits).
A6: WhatsApp Number | B6: Short Answer | C6: Optional. WhatsApp contact if different from phone.
A7: Alternate Phone | B7: Short Answer | C7: Optional. Secondary contact number.
A8: Email | B8: Short Answer | C8: Optional. Customer email for invoices/updates.
A9: City | B9: Dropdown | C9: Bangalore,Mumbai,Delhi,Hyderabad,Chennai,Pune,Other
A10: Area / Locality | B10: Short Answer | C10: e.g. Indiranagar, Koramangala, HSR Layout, Whitefield, JP Nagar
A11: Full Address | B11: Paragraph | C11: Complete address with landmark and pincode.
A12: BHK | B12: Dropdown | C12: 1BHK,2BHK,3BHK,4BHK,4+BHK,Not Applicable
A13: SQFT (Approx) | B13: Short Answer | C13: Approximate area in square feet.
A14: Service 1 | B14: Dropdown | C14: Bathroom Cleaning,Kitchen Cleaning,Full Home Cleaning,Rental Property Cleaning,Ready to Move In Cleaning,Painting,Pest Control,Plumbing,Electrician,Other
... A21: Special Instructions | B21: Paragraph | C21: Any special requirements or notes from the customer.
A23: HOW TO LINK GOOGLE FORM
A24: 1. Create a new Google Form at forms.google.com with the fields listed above.
A25: 2. Go to Responses tab in the Form > Click the Google Sheets icon to link responses.
A26: 3. A new response sheet is created automatically in Google Sheets.
A27: 4. In the Lead Tracker sheet, use IMPORTRANGE or copy-paste data from the response sheet.
A28: 5. Example: =IMPORTRANGE("spreadsheet_url", "Form Responses 1!A2:R100")
A29: 6. Map the form fields to the correct Lead Tracker columns (D, E, F, G, H, I, J, K, L, M, N, P, R, T, Y, Z, AA).
A30: 7. The Order ID (C), S.No (A), Total Value (V), Discounted Total (X), Pending Balance (AL), and Invoice (AQ) auto-populate.
A31: 8. Manually update: Order Status (AB), Vendor details (AD-AF), Payment info (AJ-AO), etc.
